Workbook

Sheet Resumen Ejecutivo
A1: Análisis de mallas curriculares y aplicación de simuladores de negocios
A2: Universidad de San Buenaventura – Facultad de Ingeniería · 7 programas de pregrado · SimVenture · SimAgile · SimProject · catálogo CompanyGame · desarrollos propios
A4: 1. Alcance del análisis
A5: Se analizaron, asignatura por asignatura, las siete láminas de plan de estudios de la Facultad de Ingeniería entregadas por el cliente, para identificar dónde pueden integrarse SimVenture, SimAgile, SimProject y el catálogo CompanyGame, y dónde existe oportunidad de desarrollar simuladores propios.
A6: No se incorporó ninguna asignatura, competencia o simulador que no aparezca en esos documentos. Los criterios de calificación son los mismos usados en el análisis de la Universidad Libre, de modo que las dos universidades son comparables.
A8: 2. Espacios académicos analizados por programa
A9: Indicador | B9: Industrial | C9: Sistemas | D9: Multimedia | E9: Agroindustrial | F9: Biomédica | G9: Electrónica | H9: Biológica | I9: Total
A10: Espacios académicos | B10: =COUNTA(Industrial!C5:C62) -> 58 | C10: =COUNTA(Sistemas!C5:C68) -> 64 | D10: =COUNTA(Multimedia!C5:C62) -> 58 | E10: =COUNTA(Agroindustrial!C5:C62) -> 58 | F10: =COUNTA(Biomédica!C5:C65) -> 61 | G10: =COUNTA(Electrónica!C5:C62) -> 58 | H10: =COUNTA(Biológica!C5:C59) -> 55 | I10: =SUM(B10:H10) -> 412
A11: Créditos del programa | B11: =SUM(Industrial!D5:D62) -> 144 | C11: =SUM(Sistemas!D5:D68) -> 160 | D11: =SUM(Multimedia!D5:D62) -> 142 | E11: =SUM(Agroindustrial!D5:D62) -> 144 | F11: =SUM(Biomédica!D5:D65) -> 156 | G11: =SUM(Electrónica!D5:D62) -> 143 | H11: =SUM(Biológica!D5:D59) -> 144 | I11: =SUM(B11:H11) -> 1033
A12: Semestres | B12: 8 | C12: 9 | D12: 8 | E12: 8 | F12: 9 | G12: 8 | H12: 8
A14: 3. Grado de ajuste con el catálogo CompanyGame (número de espacios académicos)
A15: Grado de ajuste | B15: Industrial | C15: Sistemas | D15: Multimedia | E15: Agroindustrial | F15: Biomédica | G15: Electrónica | H15: Biológica | I15: Total
A16: Encaje perfecto | B16: =COUNTIF(Industrial!O5:O62,"Encaje perfecto") -> 2 | C16: =COUNTIF(Sistemas!O5:O68,"Encaje perfecto") -> 1 | D16: =COUNTIF(Multimedia!O5:O62,"Encaje perfecto") -> 0 | E16: =COUNTIF(Agroindustrial!O5:O62,"Encaje perfecto") -> 1 | F16: =COUNTIF(Biomédica!O5:O65,"Encaje perfecto") -> 0 | G16: =COUNTIF(Electrónica!O5:O62,"Encaje perfecto") -> 0 | H16: =COUNTIF(Biológica!O5:O59,"Encaje perfecto") -> 0 | I16: =SUM(B16:H16) -> 4
A17: Encaje parcial | B17: =COUNTIF(Industrial!O5:O62,"Encaje parcial") -> 2 | C17: =COUNTIF(Sistemas!O5:O68,"Encaje parcial") -> 0 | D17: =COUNTIF(Multimedia!O5:O62,"Encaje parcial") -> 0 | E17: =COUNTIF(Agroindustrial!O5:O62,"Encaje parcial") -> 0 | F17: =COUNTIF(Biomédica!O5:O65,"Encaje parcial") -> 0 | G17: =COUNTIF(Electrónica!O5:O62,"Encaje parcial") -> 2 | H17: =COUNTIF(Biológica!O5:O59,"Encaje parcial") -> 1 | I17: =SUM(B17:H17) -> 5
A18: No encaja | B18: =COUNTIF(Industrial!O5:O62,"No encaja") -> 47 | C18: =COUNTIF(Sistemas!O5:O68,"No encaja") -> 55 | D18: =COUNTIF(Multimedia!O5:O62,"No encaja") -> 55 | E18: =COUNTIF(Agroindustrial!O5:O62,"No encaja") -> 52 | F18: =COUNTIF(Biomédica!O5:O65,"No encaja") -> 54 | G18: =COUNTIF(Electrónica!O5:O62,"No encaja") -> 52 | H18: =COUNTIF(Biológica!O5:O59,"No encaja") -> 50 | I18: =SUM(B18:H18) -> 365
A19: Por definir | B19: =COUNTIF(Industrial!O5:O62,"Por definir") -> 7 | C19: =COUNTIF(Sistemas!O5:O68,"Por definir") -> 8 | D19: =COUNTIF(Multimedia!O5:O62,"Por definir") -> 3 | E19: =COUNTIF(Agroindustrial!O5:O62,"Por definir") -> 5 | F19: =COUNTIF(Biomédica!O5:O65,"Por definir") -> 7 | G19: =COUNTIF(Electrónica!O5:O62,"Por definir") -> 4 | H19: =COUNTIF(Biológica!O5:O59,"Por definir") -> 4 | I19: =SUM(B19:H19) -> 38
A21: 4. Compatibilidad Alta o Media por simulador (número de espacios académicos)
A22: Simulador | B22: Industrial | C22: Sistemas | D22: Multimedia | E22: Agroindustrial | F22: Biomédica | G22: Electrónica | H22: Biológica | I22: Total
A23: SimVenture | B23: =COUNTIF(Industrial!J5:J62,"Alta")+COUNTIF(Industrial!J5:J62,"Media") -> 0 | C23: =COUNTIF(Sistemas!J5:J68,"Alta")+COUNTIF(Sistemas!J5:J68,"Media") -> 0 | D23: =COUNTIF(Multimedia!J5:J62,"Alta")+COUNTIF(Multimedia!J5:J62,"Media") -> 0 | E23: =COUNTIF(Agroindustrial!J5:J62,"Alta")+COUNTIF(Agroindustrial!J5:J62,"Media") -> 0 | F23: =COUNTIF(Biomédica!J5:J65,"Alta")+COUNTIF(Biomédica!J5:J65,"Media") -> 0 | G23: =COUNTIF(Electrónica!J5:J62,"Alta")+COUNTIF(Electrónica!J5:J62,"Media") -> 0 | H23: =COUNTIF(Biológica!J5:J59,"Alta")+COUNTIF(Biológica!J5:J59,"Media") -> 0 | I23: =SUM(B23:H23) -> 0
A24: SimAgile | B24: =COUNTIF(Industrial!K5:K62,"Alta")+COUNTIF(Industrial!K5:K62,"Media") -> 1 | C24: =COUNTIF(Sistemas!K5:K68,"Alta")+COUNTIF(Sistemas!K5:K68,"Media") -> 1 | D24: =COUNTIF(Multimedia!K5:K62,"Alta")+COUNTIF(Multimedia!K5:K62,"Media") -> 0 | E24: =COUNTIF(Agroindustrial!K5:K62,"Alta")+COUNTIF(Agroindustrial!K5:K62,"Media") -> 0 | F24: =COUNTIF(Biomédica!K5:K65,"Alta")+COUNTIF(Biomédica!K5:K65,"Media") -> 0 | G24: =COUNTIF(Electrónica!K5:K62,"Alta")+COUNTIF(Electrónica!K5:K62,"Media") -> 1 | H24: =COUNTIF(Biológica!K5:K59,"Alta")+COUNTIF(Biológica!K5:K59,"Media") -> 0 | I24: =SUM(B24:H24) -> 3
A25: SimProject | B25: =COUNTIF(Industrial!L5:L62,"Alta")+COUNTIF(Industrial!L5:L62,"Media") -> 1 | C25: =COUNTIF(Sistemas!L5:L68,"Alta")+COUNTIF(Sistemas!L5:L68,"Media") -> 1 | D25: =COUNTIF(Multimedia!L5:L62,"Alta")+COUNTIF(Multimedia!L5:L62,"Media") -> 1 | E25: =COUNTIF(Agroindustrial!L5:L62,"Alta")+COUNTIF(Agroindustrial!L5:L62,"Media") -> 1 | F25: =COUNTIF(Biomédica!L5:L65,"Alta")+COUNTIF(Biomédica!L5:L65,"Media") -> 1 | G25: =COUNTIF(Electrónica!L5:L62,"Alta")+COUNTIF(Electrónica!L5:L62,"Media") -> 0 | H25: =COUNTIF(Biológica!L5:L59,"Alta")+COUNTIF(Biológica!L5:L59,"Media") -> 1 | I25: =SUM(B25:H25) -> 6
A26: Desarrollo propio (oportunidad) | B26: =COUNTIF(Industrial!P5:P62,"Alta")+COUNTIF(Industrial!P5:P62,"Media") -> 21 | C26: =COUNTIF(Sistemas!P5:P68,"Alta")+COUNTIF(Sistemas!P5:P68,"Media") -> 18 | D26: =COUNTIF(Multimedia!P5:P62,"Alta")+COUNTIF(Multimedia!P5:P62,"Media") -> 15 | E26: =COUNTIF(Agroindustrial!P5:P62,"Alta")+COUNTIF(Agroindustrial!P5:P62,"Media") -> 23 | F26: =COUNTIF(Biomédica!P5:P65,"Alta")+COUNTIF(Biomédica!P5:P65,"Media") -> 16 | G26: =COUNTIF(Electrónica!P5:P62,"Alta")+COUNTIF(Electrónica!P5:P62,"Media") -> 10 | H26: =COUNTIF(Biológica!P5:P59,"Alta")+COUNTIF(Biológica!P5:P59,"Media") -> 26 | I26: =SUM(B26:H26) -> 129
A27: Todos los conteos se calculan con fórmulas sobre las hojas de programa: si se ajusta una calificación, este resumen se actualiza solo.
A29: 5. Principales hallazgos
A30: • Ingeniería Industrial es, con diferencia, el programa de mayor potencial: concentra la línea de gestión empresarial (Gestión Estratégica Organizacional, Ingeniería de Costos, Ingeniería Económica, Investigación de Mercados, Gerencia de Proyectos, Diseño de Productos y Servicios) entre los semestres 4 y 7.
A31: • Ingeniería de Sistemas tiene la línea de software más larga de la facultad (semestres 2 a 9) y es el terreno natural de SimAgile y SimProject: Análisis y Diseño de Software, Diseño de Proyectos de Software, Gestión de Proyectos de Software, los dos Proyectos de Diseño y Evaluación de Proyectos de Software.
A32: • Hallazgo principal: Ingeniería de Sistemas tiene CÁTEDRA DE EMPRENDIMIENTO (semestre 7, 3 créditos), el único espacio de emprendimiento de los siete programas. Es el encaje más natural de todo el catálogo y la puerta de entrada de la familia Emprendimiento de CompanyGame.
A33: • INTRODUCCIÓN A LA INGENIERÍA está en los siete programas: un simulador CompanyGame de nivel 1-2 (T-Shirt o Sunny Day) es la entrada de mayor volumen de estudiantes de toda la facultad, con el menor costo de entrada.
A34: • PRÁCTICA PROFESIONAL también está en los siete programas, con 6 o 7 créditos. No es la venta principal, pero es un uso de baja resistencia docente que sirve para abrir la conversación en cualquier programa.
A35: • GERENCIA DE PROYECTOS DE INGENIERÍA aparece con el mismo nombre en Industrial, Agroindustrial y Biológica: una sola demostración de SimProject puede cerrar tres cursos. El catálogo CompanyGame no tiene un simulador de dirección de proyectos, así que aquí SimProject no compite con el propio portafolio.
A36: • El sello franciscano abre la puerta de ESG: FRANCISCANISMO Y ECOLOGÍA (Sistemas y Biomédica), ECOLOGÍA AGRÍCOLA y AGRICULTURA REGENERATIVA (Biológica) son espacios donde la familia ESG Management encaja como conversación de identidad institucional y no sólo de contenido.
A37: • Ingeniería Electrónica y Ingeniería Multimedia son los programas de menor encaje con el portafolio actual: Electrónica tiene una sola asignatura de gestión (Gestión de Productos Tecnológicos) y Multimedia dos (Gestión en Proyectos y Proyecto en Ingeniería). Conviene entrar por ahí y no forzar el resto de la malla.
A38: • Ingeniería Biomédica queda prácticamente fuera del portafolio actual: sólo Valoración de Proyectos e Ingeniería Clínica I y II tienen componente de gestión. Es el programa que más justifica un desarrollo propio (gestión de tecnología hospitalaria).
A39: • La línea de producción y operaciones de Industrial, Agroindustrial y Biológica (nueve asignaturas) no tiene ningún simulador aplicable, ni propio ni del catálogo. Es el mayor vacío y el desarrollo propio con más asignaturas destino de toda la facultad.
... A43: 6. Top 15 oportunidades
A44: # | B44: Programa | C44: Sem. | D44: Asignatura | F44: Grado CG | G44: Prioridad
A45: 1 | B45: Sistemas | C45: S7 | D45: Cátedra de Emprendimiento | E45: SimVenture o la familia Emprendimiento de CompanyGame | F45: Encaje perfecto | G45: Alta
A46: 2 | B46: Industrial · Agroindustrial · Biológica | C46: S5, S6 | D46: Gerencia de Proyectos de Ingeniería | E46: SimProject | F46: Encaje parcial | G46: Alta
A47: 3 | B47: Industrial | C47: S4 | D47: Gestión Estratégica Organizacional | E47: SimVenture o Business21 / Businessglobal (CompanyGame) | F47: Encaje perfecto | G47: Alta
A48: 4 | B48: Industrial · Agroindustrial | C48: S5 | D48: Ingeniería Económica | E48: SimVenture + SimProject o Kapital (CompanyGame) | F48: Encaje perfecto | G48: Alta
...

Sheet Industrial
A1: Matriz de relacionamiento – Ingeniería Industrial
A2: Universidad de San Buenaventura – Facultad de Ingeniería · SNIES 4466 · 8 semestres · 58 espacios académicos · 144 créditos
A4: Programa | B4: Semestre | C4: Asignatura | D4: Créditos | E4: Componente de formación | F4: Área temática | G4: Competencias principales | H4: Temáticas principales | I4: Relación con gestión / negocio | J4: SimVenture | K4: SimAgile | L4: SimProject | M4: Simulador CompanyGame que encaja | N4: Nivel CG | O4: Grado de ajuste | P4: Desarrollo propio | Q4: Tipo de simulador que se requeriría | R4: Simulador recomendado | S4: Justificación de la recomendación | T4: Tipo de uso sugerido | U4: Prioridad comercial | V4: Origen de competencias y temáticas
A5: Ingeniería Industrial | B5: Semestre 1 | C5: Matemática Fundamental | D5: 3 | E5: Ciencias Básicas | F5: Ciencias básicas – matemáticas | G5: Razonamiento matemático y modelado cuantitativo | H5: Contenidos matemáticos propios del curso | I5: Nula | J5: Baja | K5: Baja | L5: Baja | M5: — | N5: — | O5: No encaja | P5: Baja | Q5: No requiere simulador — asignatura sin decisiones de gestión, proyecto o negocio | R5: Ninguno | S5: Asignatura de ciencias básicas sin decisiones de gestión, proyecto o negocio. | T5: No aplica | U5: Baja | V5: Inferencia académica
A6: Ingeniería Industrial | B6: Semestre 1 | C6: Química General | D6: 3 | E6: Ciencias Básicas | F6: Ciencias básicas – química | G6: Fundamentos químicos y trabajo experimental | H6: Contenidos químicos propios del curso; prácticas de laboratorio | I6: Nula para simuladores de gestión | J6: Baja | K6: Baja | L6: Baja | M6: — | N6: — | O6: No encaja | P6: Media | Q6: Laboratorio virtual de química (línea de producto distinta a los simuladores de gestión) | R6: Ninguno | S6: Sin relación con simuladores de gestión; oportunidad únicamente en laboratorio virtual. | T6: No aplica | U6: Baja | V6: Inferencia académica
A7: Ingeniería Industrial | B7: Semestre 1 | C7: Introducción a la Ingeniería | D7: 3 | E7: Ingeniería Aplicada | F7: Fundamentación profesional | G7: Comprensión del campo de acción del ingeniero; trabajo en equipo | H7: Perfil profesional, campos de la ingeniería, rol del ingeniero | I7: Media - contextualización profesional | J7: Baja | K7: Baja | L7: Baja | M7: — | N7: — | O7: No encaja | P7: Media | Q7: Cubierto parcialmente por el catálogo; el resto del curso se apoya en SimVenture, SimAgile o SimProject | R7: T-Shirt / Sunny Day (CompanyGame, nivel introductorio) | S7: Curso de contextualización sin decisiones de gestión, pero un simulador CompanyGame de nivel 1-2 funciona como primera experiencia de decisión empresarial en primer semestre. Está en los siete programas de la facultad, lo que lo convierte en la entrada de mayor volumen de estudiantes de toda la propuesta. | T7: Exploratorio | U7: Media | V7: Inferencia académica
A8: Ingeniería Industrial | B8: Semestre 1 | C8: Humanística I | D8: 2 | E8: Complementaria | F8: Formación humanística | G8: Formación humanística, ética y ciudadana | H8: Contenidos humanísticos propios del curso | I8: Baja | J8: Baja | K8: Baja | L8: Baja | M8: — | N8: — | O8: No encaja | P8: Baja | Q8: No requiere simulador — asignatura sin decisiones de gestión, proyecto o negocio | R8: Ninguno | S8: Formación humanística sin contenidos de gestión que justifiquen un simulador. | T8: No aplica | U8: Baja | V8: Inferencia académica
A9: Ingeniería Industrial | B9: Semestre 1 | C9: Humanística II | D9: 2 | E9: Complementaria | F9: Formación humanística | G9: Formación humanística, ética y ciudadana | H9: Contenidos humanísticos propios del curso | I9: Baja | J9: Baja | K9: Baja | L9: Baja | M9: — | N9: — | O9: No encaja | P9: Baja | Q9: No requiere simulador — asignatura sin decisiones de gestión, proyecto o negocio | R9: Ninguno | S9: Formación humanística sin contenidos de gestión que justifiquen un simulador. | T9: No aplica | U9: Baja | V9: Inferencia académica
A10: Ingeniería Industrial | B10: Semestre 1 | C10: Bienestar Institucional I | D10: 1 | E10: Complementaria | F10: Formación complementaria – bienestar | G10: Desarrollo personal y vida universitaria | H10: Actividades de bienestar institucional | I10: Nula | J10: Baja | K10: Baja | L10: Baja | M10: — | N10: — | O10: No encaja | P10: Baja | Q10: No requiere simulador — asignatura sin decisiones de gestión, proyecto o negocio | R10: Ninguno | S10: Espacio de bienestar institucional sin contenidos académicos de gestión. | T10: No aplica | U10: Baja | V10: Inferencia académica
A11: Ingeniería Industrial | B11: Semestre 1 | C11: Bienestar Institucional II | D11: 1 | E11: Complementaria | F11: Formación complementaria – bienestar | G11: Desarrollo personal y vida universitaria | H11: Actividades de bienestar institucional | I11: Nula | J11: Baja | K11: Baja | L11: Baja | M11: — | N11: — | O11: No encaja | P11: Baja | Q11: No requiere simulador — asignatura sin decisiones de gestión, proyecto o negocio | R11: Ninguno | S11: Espacio de bienestar institucional sin contenidos académicos de gestión. | T11: No aplica | U11: Baja | V11: Inferencia académica
A12: Ingeniería Industrial | B12: Semestre 1 | C12: Comunicación Oral y Escrita I | D12: 1 | E12: Complementaria | F12: Formación humanística | G12: Formación humanística, ética y ciudadana | H12: Contenidos humanísticos propios del curso | I12: Baja | J12: Baja | K12: Baja | L12: Baja | M12: — | N12: — | O12: No encaja | P12: Baja | Q12: No requiere simulador — asignatura sin decisiones de gestión, proyecto o negocio | R12: Ninguno | S12: Formación humanística sin contenidos de gestión que justifiquen un simulador. | T12: No aplica | U12: Baja | V12: Inferencia académica
A13: Ingeniería Industrial | B13: Semestre 1 | C13: Inglés I | D13: 2 | E13: Complementaria | F13: Formación complementaria – idioma | G13: Competencia comunicativa en inglés | H13: Comprensión y producción oral y escrita en inglés | I13: Nula | J13: Baja | K13: Baja | L13: Baja | M13: — | N13: — | O13: No encaja | P13: Baja | Q13: No requiere simulador — asignatura sin decisiones de gestión, proyecto o negocio | R13: Ninguno | S13: Curso de idioma sin contenidos de gestión. | T13: No aplica | U13: Baja | V13: Inferencia académica
A14: Ingeniería Industrial | B14: Semestre 2 | C14: Cálculo I | D14: 4 | E14: Ciencias Básicas | F14: Ciencias básicas – matemáticas | G14: Razonamiento matemático y modelado cuantitativo | H14: Contenidos matemáticos propios del curso | I14: Nula | J14: Baja | K14: Baja | L14: Baja | M14: — | N14: — | O14: No encaja | P14: Baja | Q14: No requiere simulador — asignatura sin decisiones de gestión, proyecto o negocio | R14: Ninguno | S14: Asignatura de ciencias básicas sin decisiones de gestión, proyecto o negocio. | T14: No aplica | U14: Baja | V14: Inferencia académica
A15: Ingeniería Industrial | B15: Semestre 2 | C15: Álgebra Lineal | D15: 3 | E15: Ciencias Básicas | F15: Ciencias básicas – matemáticas | G15: Razonamiento matemático y modelado cuantitativo | H15: Contenidos matemáticos propios del curso | I15: Nula | J15: Baja | K15: Baja | L15: Baja | M15: — | N15: — | O15: No encaja | P15: Baja | Q15: No requiere simulador — asignatura sin decisiones de gestión, proyecto o negocio | R15: Ninguno | S15: Asignatura de ciencias básicas sin decisiones de gestión, proyecto o negocio. | T15: No aplica | U15: Baja | V15: Inferencia académica
A16: Ingeniería Industrial | B16: Semestre 2 | C16: Física Mecánica | D16: 4 | E16: Ciencias Básicas | F16: Ciencias básicas – física | G16: Modelado físico de sistemas y experimentación | H16: Contenidos físicos propios del curso; trabajo de laboratorio | I16: Nula para simuladores de gestión | J16: Baja | K16: Baja | L16: Baja | M16: — | N16: — | O16: No encaja | P16: Media | Q16: Laboratorio virtual de física (línea de producto distinta a los simuladores de gestión) | R16: Ninguno | S16: Sin relación con simuladores de gestión. La única oportunidad es de laboratorio virtual, que es una línea de producto distinta. | T16: No aplica | U16: Baja | V16: Inferencia académica
... A62: Ingeniería Industrial | B62: Semestre 8 | C62: Inglés VIII | D62: 2 | E62: Complementaria | F62: Formación complementaria – idioma | G62: Competencia comunicativa en inglés | H62: Comprensión y producción oral y escrita en inglés | I62: Nula | J62: Baja | K62: Baja | L62: Baja | M62: — | N62: — | O62: No encaja | P62: Baja | Q62: No requiere simulador — asignatura sin decisiones de gestión, proyecto o negocio | R62: Ninguno | S62: Curso de idioma sin contenidos de gestión. | T62: No aplica | U62: Baja | V62: Inferencia académica
A64: Nota: Explícito en la lámina → programa, semestre, asignatura, créditos y componente de formación. Inferencia académica → área temática, competencias, temáticas, relación con la gestión y todos los niveles de compatibilidad. Grado de ajuste CompanyGame: Encaje perfecto = el simulador cubre el objeto central del curso; Encaje parcial = cubre una unidad o el contexto; No encaja = ningún simulador del catálogo aplica.

Sheet Sistemas
A1: Matriz de relacionamiento – Ingeniería de Sistemas
A2: Universidad de San Buenaventura – Facultad de Ingeniería · SNIES 1349 · 9 semestres · 64 espacios académicos · 160 créditos
A4: Programa | B4: Semestre | C4: Asignatura | D4: Créditos | E4: Componente de formación | F4: Área temática | G4: Competencias principales | H4: Temáticas principales | I4: Relación con gestión / negocio | J4: SimVenture | K4: SimAgile | L4: SimProject | M4: Simulador CompanyGame que encaja | N4: Nivel CG | O4: Grado de ajuste | P4: Desarrollo propio | Q4: Tipo de simulador que se requeriría | R4: Simulador recomendado | S4: Justificación de la recomendación | T4: Tipo de uso sugerido | U4: Prioridad comercial | V4: Origen de competencias y temáticas
A5: Ingeniería de Sistemas | B5: Semestre 1 | C5: Precálculo | D5: 3 | E5: No disponible en la fuente | F5: Ciencias básicas – matemáticas | G5: Razonamiento matemático y modelado cuantitativo | H5: Contenidos matemáticos propios del curso | I5: Nula | J5: Baja | K5: Baja | L5: Baja | M5: — | N5: — | O5: No encaja | P5: Baja | Q5: No requiere simulador — asignatura sin decisiones de gestión, proyecto o negocio | R5: Ninguno | S5: Asignatura de ciencias básicas sin decisiones de gestión, proyecto o negocio. | T5: No aplica | U5: Baja | V5: Inferencia académica
A6: Ingeniería de Sistemas | B6: Semestre 1 | C6: Matemáticas Discretas I | D6: 3 | E6: No disponible en la fuente | F6: Ciencias básicas – matemáticas | G6: Razonamiento matemático y modelado cuantitativo | H6: Contenidos matemáticos propios del curso | I6: Nula | J6: Baja | K6: Baja | L6: Baja | M6: — | N6: — | O6: No encaja | P6: Baja | Q6: No requiere simulador — asignatura sin decisiones de gestión, proyecto o negocio | R6: Ninguno | S6: Asignatura de ciencias básicas sin decisiones de gestión, proyecto o negocio. | T6: No aplica | U6: Baja | V6: Inferencia académica
A7: Ingeniería de Sistemas | B7: Semestre 1 | C7: Fundamentos de Programación | D7: 4 | E7: No disponible en la fuente | F7: Desarrollo de software – técnica | G7: Programación y resolución de problemas mediante código | H7: Contenidos técnicos de programación propios del curso | I7: Nula | J7: Baja | K7: Baja | L7: Baja | M7: — | N7: — | O7: No encaja | P7: Baja | Q7: No requiere simulador — asignatura sin decisiones de gestión, proyecto o negocio | R7: Ninguno | S7: Competencia técnica individual; no hay decisiones de gestión ni dinámica de equipo formalizada. Forzar un simulador aquí restaría credibilidad a la propuesta. | T7: No aplica | U7: Baja | V7: Inferencia académica
A8: Ingeniería de Sistemas | B8: Semestre 1 | C8: Introducción a la Ingeniería | D8: 3 | E8: No disponible en la fuente | F8: Fundamentación profesional | G8: Comprensión del campo de acción del ingeniero; trabajo en equipo | H8: Perfil profesional, campos de la ingeniería, rol del ingeniero | I8: Media - contextualización profesional | J8: Baja | K8: Baja | L8: Baja | M8: — | N8: — | O8: No encaja | P8: Media | Q8: Cubierto parcialmente por el catálogo; el resto del curso se apoya en SimVenture, SimAgile o SimProject | R8: T-Shirt / Sunny Day (CompanyGame, nivel introductorio) | S8: Curso de contextualización sin decisiones de gestión, pero un simulador CompanyGame de nivel 1-2 funciona como primera experiencia de decisión empresarial en primer semestre. Está en los siete programas de la facultad, lo que lo convierte en la entrada de mayor volumen de estudiantes de toda la propuesta. | T8: Exploratorio | U8: Media | V8: Inferencia académica
A9: Ingeniería de Sistemas | B9: Semestre 1 | C9: Expresión Oral y Escrita | D9: 2 | E9: No disponible en la fuente | F9: Formación humanística | G9: Formación humanística, ética y ciudadana | H9: Contenidos humanísticos propios del curso | I9: Baja | J9: Baja | K9: Baja | L9: Baja | M9: — | N9: — | O9: No encaja | P9: Baja | Q9: No requiere simulador — asignatura sin decisiones de gestión, proyecto o negocio | R9: Ninguno | S9: Formación humanística sin contenidos de gestión que justifiquen un simulador. | T9: No aplica | U9: Baja | V9: Inferencia académica
A10: Ingeniería de Sistemas | B10: Semestre 1 | C10: Identidad Institucional y Franciscana | D10: 1 | E10: No disponible en la fuente | F10: Formación institucional | G10: Desarrollo personal e identidad institucional | H10: Proyecto de vida, identidad y valores institucionales franciscanos | I10: Nula | J10: Baja | K10: Baja | L10: Baja | M10: — | N10: — | O10: No encaja | P10: Baja | Q10: No requiere simulador — asignatura sin decisiones de gestión, proyecto o negocio | R10: Ninguno | S10: Espacio de formación institucional sin contenidos de gestión. | T10: No aplica | U10: Baja | V10: Inferencia académica
A11: Ingeniería de Sistemas | B11: Semestre 1 | C11: Proyecto de Vida | D11: 2 | E11: No disponible en la fuente | F11: Formación institucional | G11: Desarrollo personal e identidad institucional | H11: Proyecto de vida, identidad y valores institucionales franciscanos | I11: Nula | J11: Baja | K11: Baja | L11: Baja | M11: — | N11: — | O11: No encaja | P11: Baja | Q11: No requiere simulador — asignatura sin decisiones de gestión, proyecto o negocio | R11: Ninguno | S11: Espacio de formación institucional sin contenidos de gestión. | T11: No aplica | U11: Baja | V11: Inferencia académica
A12: Ingeniería de Sistemas | B12: Semestre 1 | C12: Inglés I | D12: 0 | E12: No disponible en la fuente | F12: Formación complementaria – idioma | G12: Competencia comunicativa en inglés | H12: Comprensión y producción oral y escrita en inglés | I12: Nula | J12: Baja | K12: Baja | L12: Baja | M12: — | N12: — | O12: No encaja | P12: Baja | Q12: No requiere simulador — asignatura sin decisiones de gestión, proyecto o negocio | R12: Ninguno | S12: Curso de idioma sin contenidos de gestión. | T12: No aplica | U12: Baja | V12: Inferencia académica
A13: Ingeniería de Sistemas | B13: Semestre 2 | C13: Cálculo Diferencial | D13: 4 | E13: No disponible en la fuente | F13: Ciencias básicas – matemáticas | G13: Razonamiento matemático y modelado cuantitativo | H13: Contenidos matemáticos propios del curso | I13: Nula | J13: Baja | K13: Baja | L13: Baja | M13: — | N13: — | O13: No encaja | P13: Baja | Q13: No requiere simulador — asignatura sin decisiones de gestión, proyecto o negocio | R13: Ninguno | S13: Asignatura de ciencias básicas sin decisiones de gestión, proyecto o negocio. | T13: No aplica | U13: Baja | V13: Inferencia académica
A14: Ingeniería de Sistemas | B14: Semestre 2 | C14: Matemáticas Discretas II | D14: 3 | E14: No disponible en la fuente | F14: Ciencias básicas – matemáticas | G14: Razonamiento matemático y modelado cuantitativo | H14: Contenidos matemáticos propios del curso | I14: Nula | J14: Baja | K14: Baja | L14: Baja | M14: — | N14: — | O14: No encaja | P14: Baja | Q14: No requiere simulador — asignatura sin decisiones de gestión, proyecto o negocio | R14: Ninguno | S14: Asignatura de ciencias básicas sin decisiones de gestión, proyecto o negocio. | T14: No aplica | U14: Baja | V14: Inferencia académica
A15: Ingeniería de Sistemas | B15: Semestre 2 | C15: Programación Orientada a Objetos | D15: 4 | E15: No disponible en la fuente | F15: Desarrollo de software – técnica | G15: Programación y resolución de problemas mediante código | H15: Contenidos técnicos de programación propios del curso | I15: Nula | J15: Baja | K15: Baja | L15: Baja | M15: — | N15: — | O15: No encaja | P15: Baja | Q15: No requiere simulador — asignatura sin decisiones de gestión, proyecto o negocio | R15: Ninguno | S15: Competencia técnica individual; no hay decisiones de gestión ni dinámica de equipo formalizada. Forzar un simulador aquí restaría credibilidad a la propuesta. | T15: No aplica | U15: Baja | V15: Inferencia académica
A16: Ingeniería de Sistemas | B16: Semestre 2 | C16: Introducción a la Ingeniería de Software | D16: 2 | E16: No disponible en la fuente | F16: Ingeniería de software | G16: Ciclo de vida del software, requisitos, diseño y modelos de proceso | H16: Modelos de proceso (predictivos y ágiles), requisitos, diseño, modelado | I16: Alta - proceso, equipo y producto de software | J16: Baja | K16: Baja | L16: Baja | M16: — | N16: — | O16: No encaja | P16: Media | Q16: Cubierto parcialmente por el catálogo; el resto del curso se apoya en SimVenture, SimAgile o SimProject | R16: SimAgile | S16: Es donde se enseñan los marcos ágiles: SimAgile permite que el estudiante viva un ciclo completo de trabajo en equipo en lugar de memorizar roles y ceremonias. Encaje directo con una unidad completa del curso. | T16: Principal | U16: Alta | V16: Inferencia académica
... A68: Ingeniería de Sistemas | B68: Semestre 9 | C68: Ética | D68: 2 | E68: No disponible en la fuente | F68: Formación humanística – ética | G68: Razonamiento ético aplicado al ejercicio profesional | H68: Teorías éticas, ética profesional, dilemas de la práctica | I68: Baja - dilemas éticos en la decisión profesional | J68: Baja | K68: Baja | L68: Baja | M68: — | N68: — | O68: No encaja | P68: Media | Q68: DP-07: simulador de dilemas éticos en la decisión profesional | R68: ESGProject (CompanyGame) o desarrollo propio (DP-07) | S68: Los simuladores de gestión no modelan consecuencias éticas de la decisión; ESGProject cubre parcialmente la dimensión de sostenibilidad y responsabilidad. El dilema ético profesional propiamente dicho es una oportunidad de desarrollo propio transversal. | T68: Exploratorio | U68: Baja | V68: Inferencia académica
A70: Nota: Explícito en la lámina → programa, semestre, asignatura, créditos y componente de formación. Inferencia académica → área temática, competencias, temáticas, relación con la gestión y todos los niveles de compatibilidad. Grado de ajuste CompanyGame: Encaje perfecto = el simulador cubre el objeto central del curso; Encaje parcial = cubre una unidad o el contexto; No encaja = ningún simulador del catálogo aplica.

Sheet Multimedia
A1: Matriz de relacionamiento – Ingeniería Multimedia
A2: Universidad de San Buenaventura – Facultad de Ingeniería · 8 semestres · 58 espacios académicos · 142 créditos
A4: Programa | B4: Semestre | C4: Asignatura | D4: Créditos | E4: Componente de formación | F4: Área temática | G4: Competencias principales | H4: Temáticas principales | I4: Relación con gestión / negocio | J4: SimVenture | K4: SimAgile | L4: SimProject | M4: Simulador CompanyGame que encaja | N4: Nivel CG | O4: Grado de ajuste | P4: Desarrollo propio | Q4: Tipo de simulador que se requeriría | R4: Simulador recomendado | S4: Justificación de la recomendación | T4: Tipo de uso sugerido | U4: Prioridad comercial | V4: Origen de competencias y temáticas
A5: Ingeniería Multimedia | B5: Semestre 1 | C5: Precálculo | D5: 3 | E5: Ciencias Básicas | F5: Ciencias básicas – matemáticas | G5: Razonamiento matemático y modelado cuantitativo | H5: Contenidos matemáticos propios del curso | I5: Nula | J5: Baja | K5: Baja | L5: Baja | M5: — | N5: — | O5: No encaja | P5: Baja | Q5: No requiere simulador — asignatura sin decisiones de gestión, proyecto o negocio | R5: Ninguno | S5: Asignatura de ciencias básicas sin decisiones de gestión, proyecto o negocio. | T5: No aplica | U5: Baja | V5: Inferencia académica
A6: Ingeniería Multimedia | B6: Semestre 1 | C6: Matemáticas Discretas | D6: 3 | E6: Ciencias Básicas | F6: Ciencias básicas – matemáticas | G6: Razonamiento matemático y modelado cuantitativo | H6: Contenidos matemáticos propios del curso | I6: Nula | J6: Baja | K6: Baja | L6: Baja | M6: — | N6: — | O6: No encaja | P6: Baja | Q6: No requiere simulador — asignatura sin decisiones de gestión, proyecto o negocio | R6: Ninguno | S6: Asignatura de ciencias básicas sin decisiones de gestión, proyecto o negocio. | T6: No aplica | U6: Baja | V6: Inferencia académica
A7: Ingeniería Multimedia | B7: Semestre 1 | C7: Fundamentos de Programación | D7: 3 | E7: Ciencias Básicas de Ingeniería | F7: Desarrollo de software – técnica | G7: Programación y resolución de problemas mediante código | H7: Contenidos técnicos de programación propios del curso | I7: Nula | J7: Baja | K7: Baja | L7: Baja | M7: — | N7: — | O7: No encaja | P7: Baja | Q7: No requiere simulador — asignatura sin decisiones de gestión, proyecto o negocio | R7: Ninguno | S7: Competencia técnica individual; no hay decisiones de gestión ni dinámica de equipo formalizada. Forzar un simulador aquí restaría credibilidad a la propuesta. | T7: No aplica | U7: Baja | V7: Inferencia académica
A8: Ingeniería Multimedia | B8: Semestre 1 | C8: Introducción a la Ingeniería | D8: 3 | E8: Ciencias Básicas de Ingeniería | F8: Fundamentación profesional | G8: Comprensión del campo de acción del ingeniero; trabajo en equipo | H8: Perfil profesional, campos de la ingeniería, rol del ingeniero | I8: Media - contextualización profesional | J8: Baja | K8: Baja | L8: Baja | M8: — | N8: — | O8: No encaja | P8: Media | Q8: Cubierto parcialmente por el catálogo; el resto del curso se apoya en SimVenture, SimAgile o SimProject | R8: T-Shirt / Sunny Day (CompanyGame, nivel introductorio) | S8: Curso de contextualización sin decisiones de gestión, pero un simulador CompanyGame de nivel 1-2 funciona como primera experiencia de decisión empresarial en primer semestre. Está en los siete programas de la facultad, lo que lo convierte en la entrada de mayor volumen de estudiantes de toda la propuesta. | T8: Exploratorio | U8: Media | V8: Inferencia académica
A9: Ingeniería Multimedia | B9: Semestre 1 | C9: Comunicación Oral y Escrita I | D9: 1 | E9: Complementaria | F9: Formación humanística | G9: Formación humanística, ética y ciudadana | H9: Contenidos humanísticos propios del curso | I9: Baja | J9: Baja | K9: Baja | L9: Baja | M9: — | N9: — | O9: No encaja | P9: Baja | Q9: No requiere simulador — asignatura sin decisiones de gestión, proyecto o negocio | R9: Ninguno | S9: Formación humanística sin contenidos de gestión que justifiquen un simulador. | T9: No aplica | U9: Baja | V9: Inferencia académica
A10: Ingeniería Multimedia | B10: Semestre 1 | C10: Humanística I | D10: 2 | E10: Complementaria | F10: Formación humanística | G10: Formación humanística, ética y ciudadana | H10: Contenidos humanísticos propios del curso | I10: Baja | J10: Baja | K10: Baja | L10: Baja | M10: — | N10: — | O10: No encaja | P10: Baja | Q10: No requiere simulador — asignatura sin decisiones de gestión, proyecto o negocio | R10: Ninguno | S10: Formación humanística sin contenidos de gestión que justifiquen un simulador. | T10: No aplica | U10: Baja | V10: Inferencia académica
A11: Ingeniería Multimedia | B11: Semestre 1 | C11: Humanística II | D11: 2 | E11: Complementaria | F11: Formación humanística | G11: Formación humanística, ética y ciudadana | H11: Contenidos humanísticos propios del curso | I11: Baja | J11: Baja | K11: Baja | L11: Baja | M11: — | N11: — | O11: No encaja | P11: Baja | Q11: No requiere simulador — asignatura sin decisiones de gestión, proyecto o negocio | R11: Ninguno | S11: Formación humanística sin contenidos de gestión que justifiquen un simulador. | T11: No aplica | U11: Baja | V11: Inferencia académica
A12: Ingeniería Multimedia | B12: Semestre 1 | C12: Inglés I | D12: 2 | E12: Complementaria | F12: Formación complementaria – idioma | G12: Competencia comunicativa en inglés | H12: Comprensión y producción oral y escrita en inglés | I12: Nula | J12: Baja | K12: Baja | L12: Baja | M12: — | N12: — | O12: No encaja | P12: Baja | Q12: No requiere simulador — asignatura sin decisiones de gestión, proyecto o negocio | R12: Ninguno | S12: Curso de idioma sin contenidos de gestión. | T12: No aplica | U12: Baja | V12: Inferencia académica
A13: Ingeniería Multimedia | B13: Semestre 2 | C13: Física Mecánica | D13: 4 | E13: Ciencias Básicas | F13: Ciencias básicas – física | G13: Modelado físico de sistemas y experimentación | H13: Contenidos físicos propios del curso; trabajo de laboratorio | I13: Nula para simuladores de gestión | J13: Baja | K13: Baja | L13: Baja | M13: — | N13: — | O13: No encaja | P13: Media | Q13: Laboratorio virtual de física (línea de producto distinta a los simuladores de gestión) | R13: Ninguno | S13: Sin relación con simuladores de gestión. La única oportunidad es de laboratorio virtual, que es una línea de producto distinta. | T13: No aplica | U13: Baja | V13: Inferencia académica
A14: Ingeniería Multimedia | B14: Semestre 2 | C14: Cálculo I | D14: 4 | E14: Ciencias Básicas | F14: Ciencias básicas – matemáticas | G14: Razonamiento matemático y modelado cuantitativo | H14: Contenidos matemáticos propios del curso | I14: Nula | J14: Baja | K14: Baja | L14: Baja | M14: — | N14: — | O14: No encaja | P14: Baja | Q14: No requiere simulador — asignatura sin decisiones de gestión, proyecto o negocio | R14: Ninguno | S14: Asignatura de ciencias básicas sin decisiones de gestión, proyecto o negocio. | T14: No aplica | U14: Baja | V14: Inferencia académica
A15: Ingeniería Multimedia | B15: Semestre 2 | C15: Programación Orientada a Objetos | D15: 3 | E15: Ciencias Básicas de Ingeniería | F15: Desarrollo de software – técnica | G15: Programación y resolución de problemas mediante código | H15: Contenidos técnicos de programación propios del curso | I15: Nula | J15: Baja | K15: Baja | L15: Baja | M15: — | N15: — | O15: No encaja | P15: Baja | Q15: No requiere simulador — asignatura sin decisiones de gestión, proyecto o negocio | R15: Ninguno | S15: Competencia técnica individual; no hay decisiones de gestión ni dinámica de equipo formalizada. Forzar un simulador aquí restaría credibilidad a la propuesta. | T15: No aplica | U15: Baja | V15: Inferencia académica
A16: Ingeniería Multimedia | B16: Semestre 2 | C16: Taller Multimedia | D16: 2 | E16: Ingeniería Aplicada | F16: Producción de medios digitales | G16: Producción y postproducción de contenidos digitales | H16: Contenidos técnicos y creativos propios del curso | I16: Baja | J16: Baja | K16: Baja | L16: Baja | M16: — | N16: — | O16: No encaja | P16: Media | Q16: DP-11: simulador de gestión de una producción audiovisual (presupuesto, cronograma y equipo creativo) | R16: Ninguno | S16: Producción creativa sin decisiones de gestión modeladas por el portafolio. Un simulador propio de gestión de producción audiovisual sería la única vía. | T16: No aplica | U16: Baja | V16: Inferencia académica
... A62: Ingeniería Multimedia | B62: Semestre 8 | C62: Inglés VIII | D62: 2 | E62: Complementaria | F62: Formación complementaria – idioma | G62: Competencia comunicativa en inglés | H62: Comprensión y producción oral y escrita en inglés | I62: Nula | J62: Baja | K62: Baja | L62: Baja | M62: — | N62: — | O62: No encaja | P62: Baja | Q62: No requiere simulador — asignatura sin decisiones de gestión, proyecto o negocio | R62: Ninguno | S62: Curso de idioma sin contenidos de gestión. | T62: No aplica | U62: Baja | V62: Inferencia académica
A64: Nota: Explícito en la lámina → programa, semestre, asignatura, créditos y componente de formación. Inferencia académica → área temática, competencias, temáticas, relación con la gestión y todos los niveles de compatibilidad. Grado de ajuste CompanyGame: Encaje perfecto = el simulador cubre el objeto central del curso; Encaje parcial = cubre una unidad o el contexto; No encaja = ningún simulador del catálogo aplica.

Sheet Agroindustrial
A1: Matriz de relacionamiento – Ingeniería Agroindustrial
A2: Universidad de San Buenaventura – Facultad de Ingeniería · 8 semestres · 58 espacios académicos · 144 créditos
A4: Programa | B4: Semestre | C4: Asignatura | D4: Créditos | E4: Componente de formación | F4: Área temática | G4: Competencias principales | H4: Temáticas principales | I4: Relación con gestión / negocio | J4: SimVenture | K4: SimAgile | L4: SimProject | M4: Simulador CompanyGame que encaja | N4: Nivel CG | O4: Grado de ajuste | P4: Desarrollo propio | Q4: Tipo de simulador que se requeriría | R4: Simulador recomendado | S4: Justificación de la recomendación | T4: Tipo de uso sugerido | U4: Prioridad comercial | V4: Origen de competencias y temáticas
A5: Ingeniería Agroindustrial | B5: Semestre 1 | C5: Matemáticas Fundamentales | D5: 3 | E5: Ciencias Básicas | F5: Ciencias básicas – matemáticas | G5: Razonamiento matemático y modelado cuantitativo | H5: Contenidos matemáticos propios del curso | I5: Nula | J5: Baja | K5: Baja | L5: Baja | M5: — | N5: — | O5: No encaja | P5: Baja | Q5: No requiere simulador — asignatura sin decisiones de gestión, proyecto o negocio | R5: Ninguno | S5: Asignatura de ciencias básicas sin decisiones de gestión, proyecto o negocio. | T5: No aplica | U5: Baja | V5: Inferencia académica
A6: Ingeniería Agroindustrial | B6: Semestre 1 | C6: Química | D6: 3 | E6: Ciencias Básicas | F6: Ciencias básicas – química | G6: Fundamentos químicos y trabajo experimental | H6: Contenidos químicos propios del curso; prácticas de laboratorio | I6: Nula para simuladores de gestión | J6: Baja | K6: Baja | L6: Baja | M6: — | N6: — | O6: No encaja | P6: Media | Q6: Laboratorio virtual de química (línea de producto distinta a los simuladores de gestión) | R6: Ninguno | S6: Sin relación con simuladores de gestión; oportunidad únicamente en laboratorio virtual. | T6: No aplica | U6: Baja | V6: Inferencia académica
A7: Ingeniería Agroindustrial | B7: Semestre 1 | C7: Introducción a la Ingeniería | D7: 3 | E7: Ciencias Básicas de Ingeniería | F7: Fundamentación profesional | G7: Comprensión del campo de acción del ingeniero; trabajo en equipo | H7: Perfil profesional, campos de la ingeniería, rol del ingeniero | I7: Media - contextualización profesional | J7: Baja | K7: Baja | L7: Baja | M7: — | N7: — | O7: No encaja | P7: Media | Q7: Cubierto parcialmente por el catálogo; el resto del curso se apoya en SimVenture, SimAgile o SimProject | R7: T-Shirt / Sunny Day (CompanyGame, nivel introductorio) | S7: Curso de contextualización sin decisiones de gestión, pero un simulador CompanyGame de nivel 1-2 funciona como primera experiencia de decisión empresarial en primer semestre. Está en los siete programas de la facultad, lo que lo convierte en la entrada de mayor volumen de estudiantes de toda la propuesta. | T7: Exploratorio | U7: Media | V7: Inferencia académica
A8: Ingeniería Agroindustrial | B8: Semestre 1 | C8: Humanística I | D8: 2 | E8: Complementaria | F8: Formación humanística | G8: Formación humanística, ética y ciudadana | H8: Contenidos humanísticos propios del curso | I8: Baja | J8: Baja | K8: Baja | L8: Baja | M8: — | N8: — | O8: No encaja | P8: Baja | Q8: No requiere simulador — asignatura sin decisiones de gestión, proyecto o negocio | R8: Ninguno | S8: Formación humanística sin contenidos de gestión que justifiquen un simulador. | T8: No aplica | U8: Baja | V8: Inferencia académica
A9: Ingeniería Agroindustrial | B9: Semestre 1 | C9: Humanística II | D9: 2 | E9: Complementaria | F9: Formación humanística | G9: Formación humanística, ética y ciudadana | H9: Contenidos humanísticos propios del curso | I9: Baja | J9: Baja | K9: Baja | L9: Baja | M9: — | N9: — | O9: No encaja | P9: Baja | Q9: No requiere simulador — asignatura sin decisiones de gestión, proyecto o negocio | R9: Ninguno | S9: Formación humanística sin contenidos de gestión que justifiquen un simulador. | T9: No aplica | U9: Baja | V9: Inferencia académica
A10: Ingeniería Agroindustrial | B10: Semestre 1 | C10: Curso Formativo de Bienestar Institucional I | D10: 1 | E10: Complementaria | F10: Formación complementaria – bienestar | G10: Desarrollo personal y vida universitaria | H10: Actividades de bienestar institucional | I10: Nula | J10: Baja | K10: Baja | L10: Baja | M10: — | N10: — | O10: No encaja | P10: Baja | Q10: No requiere simulador — asignatura sin decisiones de gestión, proyecto o negocio | R10: Ninguno | S10: Espacio de bienestar institucional sin contenidos académicos de gestión. | T10: No aplica | U10: Baja | V10: Inferencia académica
A11: Ingeniería Agroindustrial | B11: Semestre 1 | C11: Curso Formativo de Bienestar Institucional II | D11: 1 | E11: Complementaria | F11: Formación complementaria – bienestar | G11: Desarrollo personal y vida universitaria | H11: Actividades de bienestar institucional | I11: Nula | J11: Baja | K11: Baja | L11: Baja | M11: — | N11: — | O11: No encaja | P11: Baja | Q11: No requiere simulador — asignatura sin decisiones de gestión, proyecto o negocio | R11: Ninguno | S11: Espacio de bienestar institucional sin contenidos académicos de gestión. | T11: No aplica | U11: Baja | V11: Inferencia académica
A12: Ingeniería Agroindustrial | B12: Semestre 1 | C12: Comunicación Oral y Escrita I | D12: 1 | E12: Complementaria | F12: Formación humanística | G12: Formación humanística, ética y ciudadana | H12: Contenidos humanísticos propios del curso | I12: Baja | J12: Baja | K12: Baja | L12: Baja | M12: — | N12: — | O12: No encaja | P12: Baja | Q12: No requiere simulador — asignatura sin decisiones de gestión, proyecto o negocio | R12: Ninguno | S12: Formación humanística sin contenidos de gestión que justifiquen un simulador. | T12: No aplica | U12: Baja | V12: Inferencia académica
A13: Ingeniería Agroindustrial | B13: Semestre 1 | C13: Inglés I | D13: 2 | E13: Complementaria | F13: Formación complementaria – idioma | G13: Competencia comunicativa en inglés | H13: Comprensión y producción oral y escrita en inglés | I13: Nula | J13: Baja | K13: Baja | L13: Baja | M13: — | N13: — | O13: No encaja | P13: Baja | Q13: No requiere simulador — asignatura sin decisiones de gestión, proyecto o negocio | R13: Ninguno | S13: Curso de idioma sin contenidos de gestión. | T13: No aplica | U13: Baja | V13: Inferencia académica
A14: Ingeniería Agroindustrial | B14: Semestre 2 | C14: Física Mecánica | D14: 4 | E14: Ciencias Básicas | F14: Ciencias básicas – física | G14: Modelado físico de sistemas y experimentación | H14: Contenidos físicos propios del curso; trabajo de laboratorio | I14: Nula para simuladores de gestión | J14: Baja | K14: Baja | L14: Baja | M14: — | N14: — | O14: No encaja | P14: Media | Q14: Laboratorio virtual de física (línea de producto distinta a los simuladores de gestión) | R14: Ninguno | S14: Sin relación con simuladores de gestión. La única oportunidad es de laboratorio virtual, que es una línea de producto distinta. | T14: No aplica | U14: Baja | V14: Inferencia académica
A15: Ingeniería Agroindustrial | B15: Semestre 2 | C15: Cálculo I | D15: 4 | E15: Ciencias Básicas | F15: Ciencias básicas – matemáticas | G15: Razonamiento matemático y modelado cuantitativo | H15: Contenidos matemáticos propios del curso | I15: Nula | J15: Baja | K15: Baja | L15: Baja | M15: — | N15: — | O15: No encaja | P15: Baja | Q15: No requiere simulador — asignatura sin decisiones de gestión, proyecto o negocio | R15: Ninguno | S15: Asignatura de ciencias básicas sin decisiones de gestión, proyecto o negocio. | T15: No aplica | U15: Baja | V15: Inferencia académica
A16: Ingeniería Agroindustrial | B16: Semestre 2 | C16: Bioquímica | D16: 3 | E16: Ciencias Básicas | F16: Ciencias básicas – química | G16: Fundamentos químicos y trabajo experimental | H16: Contenidos químicos propios del curso; prácticas de laboratorio | I16: Nula para simuladores de gestión | J16: Baja | K16: Baja | L16: Baja | M16: — | N16: — | O16: No encaja | P16: Media | Q16: Laboratorio virtual de química (línea de producto distinta a los simuladores de gestión) | R16: Ninguno | S16: Sin relación con simuladores de gestión; oportunidad únicamente en laboratorio virtual. | T16: No aplica | U16: Baja | V16: Inferencia académica
... A62: Ingeniería Agroindustrial | B62: Semestre 8 | C62: Inglés VIII | D62: 2 | E62: Complementaria | F62: Formación complementaria – idioma | G62: Competencia comunicativa en inglés | H62: Comprensión y producción oral y escrita en inglés | I62: Nula | J62: Baja | K62: Baja | L62: Baja | M62: — | N62: — | O62: No encaja | P62: Baja | Q62: No requiere simulador — asignatura sin decisiones de gestión, proyecto o negocio | R62: Ninguno | S62: Curso de idioma sin contenidos de gestión. | T62: No aplica | U62: Baja | V62: Inferencia académica
A64: Nota: Explícito en la lámina → programa, semestre, asignatura, créditos y componente de formación. Inferencia académica → área temática, competencias, temáticas, relación con la gestión y todos los niveles de compatibilidad. Grado de ajuste CompanyGame: Encaje perfecto = el simulador cubre el objeto central del curso; Encaje parcial = cubre una unidad o el contexto; No encaja = ningún simulador del catálogo aplica.

Sheet Biomédica
A1: Matriz de relacionamiento – Ingeniería Biomédica
A2: Universidad de San Buenaventura – Facultad de Ingeniería · 9 semestres · 61 espacios académicos · 156 créditos
A4: Programa | B4: Semestre | C4: Asignatura | D4: Créditos | E4: Componente de formación | F4: Área temática | G4: Competencias principales | H4: Temáticas principales | I4: Relación con gestión / negocio | J4: SimVenture | K4: SimAgile | L4: SimProject | M4: Simulador CompanyGame que encaja | N4: Nivel CG | O4: Grado de ajuste | P4: Desarrollo propio | Q4: Tipo de simulador que se requeriría | R4: Simulador recomendado | S4: Justificación de la recomendación | T4: Tipo de uso sugerido | U4: Prioridad comercial | V4: Origen de competencias y temáticas
A5: Ingeniería Biomédica | B5: Semestre 1 | C5: Biología Celular | D5: 3 | E5: Ciencias Básicas | F5: Ciencias básicas – biología y bioprocesos | G5: Fundamentos biológicos aplicados a la ingeniería | H5: Contenidos biológicos y de bioprocesos propios del curso | I5: Nula para simuladores de gestión | J5: Baja | K5: Baja | L5: Baja | M5: — | N5: — | O5: No encaja | P5: Media | Q5: Laboratorio o simulador virtual de bioprocesos (línea de producto distinta) | R5: Ninguno | S5: Contenido científico-técnico sin decisiones de gestión. La oportunidad sería un laboratorio o simulador de bioprocesos, línea distinta a los simuladores de negocio. | T5: No aplica | U5: Baja | V5: Inferencia académica
A6: Ingeniería Biomédica | B6: Semestre 1 | C6: Precálculo | D6: 3 | E6: Ciencias Básicas | F6: Ciencias básicas – matemáticas | G6: Razonamiento matemático y modelado cuantitativo | H6: Contenidos matemáticos propios del curso | I6: Nula | J6: Baja | K6: Baja | L6: Baja | M6: — | N6: — | O6: No encaja | P6: Baja | Q6: No requiere simulador — asignatura sin decisiones de gestión, proyecto o negocio | R6: Ninguno | S6: Asignatura de ciencias básicas sin decisiones de gestión, proyecto o negocio. | T6: No aplica | U6: Baja | V6: Inferencia académica
A7: Ingeniería Biomédica | B7: Semestre 1 | C7: Dibujo para Ingeniería | D7: 2 | E7: Ciencias Básicas de Ingeniería | F7: Electrónica, hardware e infraestructura | G7: Diseño y operación de sistemas electrónicos y de infraestructura | H7: Contenidos técnicos propios del curso | I7: Nula | J7: Baja | K7: Baja | L7: Baja | M7: — | N7: — | O7: No encaja | P7: Baja | Q7: No requiere simulador — asignatura sin decisiones de gestión, proyecto o negocio | R7: Ninguno | S7: Dominio técnico sin decisiones de gestión, proyecto o negocio. | T7: No aplica | U7: Baja | V7: Inferencia académica
A8: Ingeniería Biomédica | B8: Semestre 1 | C8: Introducción a la Ingeniería | D8: 3 | E8: Ciencias Básicas de Ingeniería | F8: Fundamentación profesional | G8: Comprensión del campo de acción del ingeniero; trabajo en equipo | H8: Perfil profesional, campos de la ingeniería, rol del ingeniero | I8: Media - contextualización profesional | J8: Baja | K8: Baja | L8: Baja | M8: — | N8: — | O8: No encaja | P8: Media | Q8: Cubierto parcialmente por el catálogo; el resto del curso se apoya en SimVenture, SimAgile o SimProject | R8: T-Shirt / Sunny Day (CompanyGame, nivel introductorio) | S8: Curso de contextualización sin decisiones de gestión, pero un simulador CompanyGame de nivel 1-2 funciona como primera experiencia de decisión empresarial en primer semestre. Está en los siete programas de la facultad, lo que lo convierte en la entrada de mayor volumen de estudiantes de toda la propuesta. | T8: Exploratorio | U8: Media | V8: Inferencia académica
A9: Ingeniería Biomédica | B9: Semestre 1 | C9: Expresión Oral y Escrita | D9: 1 | E9: Complementaria | F9: Formación humanística | G9: Formación humanística, ética y ciudadana | H9: Contenidos humanísticos propios del curso | I9: Baja | J9: Baja | K9: Baja | L9: Baja | M9: — | N9: — | O9: No encaja | P9: Baja | Q9: No requiere simulador — asignatura sin decisiones de gestión, proyecto o negocio | R9: Ninguno | S9: Formación humanística sin contenidos de gestión que justifiquen un simulador. | T9: No aplica | U9: Baja | V9: Inferencia académica
A10: Ingeniería Biomédica | B10: Semestre 1 | C10: Identidad Institucional y Franciscana | D10: 1 | E10: Complementaria | F10: Formación institucional | G10: Desarrollo personal e identidad institucional | H10: Proyecto de vida, identidad y valores institucionales franciscanos | I10: Nula | J10: Baja | K10: Baja | L10: Baja | M10: — | N10: — | O10: No encaja | P10: Baja | Q10: No requiere simulador — asignatura sin decisiones de gestión, proyecto o negocio | R10: Ninguno | S10: Espacio de formación institucional sin contenidos de gestión. | T10: No aplica | U10: Baja | V10: Inferencia académica
A11: Ingeniería Biomédica | B11: Semestre 1 | C11: Proyecto de Vida | D11: 2 | E11: Complementaria | F11: Formación institucional | G11: Desarrollo personal e identidad institucional | H11: Proyecto de vida, identidad y valores institucionales franciscanos | I11: Nula | J11: Baja | K11: Baja | L11: Baja | M11: — | N11: — | O11: No encaja | P11: Baja | Q11: No requiere simulador — asignatura sin decisiones de gestión, proyecto o negocio | R11: Ninguno | S11: Espacio de formación institucional sin contenidos de gestión. | T11: No aplica | U11: Baja | V11: Inferencia académica
A12: Ingeniería Biomédica | B12: Semestre 1 | C12: Bienestar Institucional I | D12: 1 | E12: Complementaria | F12: Formación complementaria – bienestar | G12: Desarrollo personal y vida universitaria | H12: Actividades de bienestar institucional | I12: Nula | J12: Baja | K12: Baja | L12: Baja | M12: — | N12: — | O12: No encaja | P12: Baja | Q12: No requiere simulador — asignatura sin decisiones de gestión, proyecto o negocio | R12: Ninguno | S12: Espacio de bienestar institucional sin contenidos académicos de gestión. | T12: No aplica | U12: Baja | V12: Inferencia académica
A13: Ingeniería Biomédica | B13: Semestre 1 | C13: Inglés I | D13: 1 | E13: Complementaria | F13: Formación complementaria – idioma | G13: Competencia comunicativa en inglés | H13: Comprensión y producción oral y escrita en inglés | I13: Nula | J13: Baja | K13: Baja | L13: Baja | M13: — | N13: — | O13: No encaja | P13: Baja | Q13: No requiere simulador — asignatura sin decisiones de gestión, proyecto o negocio | R13: Ninguno | S13: Curso de idioma sin contenidos de gestión. | T13: No aplica | U13: Baja | V13: Inferencia académica
A14: Ingeniería Biomédica | B14: Semestre 2 | C14: Física Mecánica | D14: 4 | E14: Ciencias Básicas | F14: Ciencias básicas – física | G14: Modelado físico de sistemas y experimentación | H14: Contenidos físicos propios del curso; trabajo de laboratorio | I14: Nula para simuladores de gestión | J14: Baja | K14: Baja | L14: Baja | M14: — | N14: — | O14: No encaja | P14: Media | Q14: Laboratorio virtual de física (línea de producto distinta a los simuladores de gestión) | R14: Ninguno | S14: Sin relación con simuladores de gestión. La única oportunidad es de laboratorio virtual, que es una línea de producto distinta. | T14: No aplica | U14: Baja | V14: Inferencia académica
A15: Ingeniería Biomédica | B15: Semestre 2 | C15: Química | D15: 4 | E15: Ciencias Básicas | F15: Ciencias básicas – química | G15: Fundamentos químicos y trabajo experimental | H15: Contenidos químicos propios del curso; prácticas de laboratorio | I15: Nula para simuladores de gestión | J15: Baja | K15: Baja | L15: Baja | M15: — | N15: — | O15: No encaja | P15: Media | Q15: Laboratorio virtual de química (línea de producto distinta a los simuladores de gestión) | R15: Ninguno | S15: Sin relación con simuladores de gestión; oportunidad únicamente en laboratorio virtual. | T15: No aplica | U15: Baja | V15: Inferencia académica
A16: Ingeniería Biomédica | B16: Semestre 2 | C16: Cálculo Diferencial | D16: 4 | E16: Ciencias Básicas | F16: Ciencias básicas – matemáticas | G16: Razonamiento matemático y modelado cuantitativo | H16: Contenidos matemáticos propios del curso | I16: Nula | J16: Baja | K16: Baja | L16: Baja | M16: — | N16: — | O16: No encaja | P16: Baja | Q16: No requiere simulador — asignatura sin decisiones de gestión, proyecto o negocio | R16: Ninguno | S16: Asignatura de ciencias básicas sin decisiones de gestión, proyecto o negocio. | T16: No aplica | U16: Baja | V16: Inferencia académica
... A65: Ingeniería Biomédica | B65: Semestre 9 | C65: Inglés VIII | D65: 1 | E65: Complementaria | F65: Formación complementaria – idioma | G65: Competencia comunicativa en inglés | H65: Comprensión y producción oral y escrita en inglés | I65: Nula | J65: Baja | K65: Baja | L65: Baja | M65: — | N65: — | O65: No encaja | P65: Baja | Q65: No requiere simulador — asignatura sin decisiones de gestión, proyecto o negocio | R65: Ninguno | S65: Curso de idioma sin contenidos de gestión. | T65: No aplica | U65: Baja | V65: Inferencia académica
A67: Nota: Explícito en la lámina → programa, semestre, asignatura, créditos y componente de formación. Inferencia académica → área temática, competencias, temáticas, relación con la gestión y todos los niveles de compatibilidad. Grado de ajuste CompanyGame: Encaje perfecto = el simulador cubre el objeto central del curso; Encaje parcial = cubre una unidad o el contexto; No encaja = ningún simulador del catálogo aplica.

Sheet Electrónica
A1: Matriz de relacionamiento – Ingeniería Electrónica
A2: Universidad de San Buenaventura – Facultad de Ingeniería · SNIES 3828 · 8 semestres · 58 espacios académicos · 143 créditos
A4: Programa | B4: Semestre | C4: Asignatura | D4: Créditos | E4: Componente de formación | F4: Área temática | G4: Competencias principales | H4: Temáticas principales | I4: Relación con gestión / negocio | J4: SimVenture | K4: SimAgile | L4: SimProject | M4: Simulador CompanyGame que encaja | N4: Nivel CG | O4: Grado de ajuste | P4: Desarrollo propio | Q4: Tipo de simulador que se requeriría | R4: Simulador recomendado | S4: Justificación de la recomendación | T4: Tipo de uso sugerido | U4: Prioridad comercial | V4: Origen de competencias y temáticas
A5: Ingeniería Electrónica | B5: Semestre 1 | C5: Introducción a la Ingeniería | D5: 3 | E5: Ciencias Básicas de Ingeniería | F5: Fundamentación profesional | G5: Comprensión del campo de acción del ingeniero; trabajo en equipo | H5: Perfil profesional, campos de la ingeniería, rol del ingeniero | I5: Media - contextualización profesional | J5: Baja | K5: Baja | L5: Baja | M5: — | N5: — | O5: No encaja | P5: Media | Q5: Cubierto parcialmente por el catálogo; el resto del curso se apoya en SimVenture, SimAgile o SimProject | R5: T-Shirt / Sunny Day (CompanyGame, nivel introductorio) | S5: Curso de contextualización sin decisiones de gestión, pero un simulador CompanyGame de nivel 1-2 funciona como primera experiencia de decisión empresarial en primer semestre. Está en los siete programas de la facultad, lo que lo convierte en la entrada de mayor volumen de estudiantes de toda la propuesta. | T5: Exploratorio | U5: Media | V5: Inferencia académica
A6: Ingeniería Electrónica | B6: Semestre 1 | C6: Comunicación Oral y Escrita I | D6: 1 | E6: Ciencias Básicas de Ingeniería | F6: Formación humanística | G6: Formación humanística, ética y ciudadana | H6: Contenidos humanísticos propios del curso | I6: Baja | J6: Baja | K6: Baja | L6: Baja | M6: — | N6: — | O6: No encaja | P6: Baja | Q6: No requiere simulador — asignatura sin decisiones de gestión, proyecto o negocio | R6: Ninguno | S6: Formación humanística sin contenidos de gestión que justifiquen un simulador. | T6: No aplica | U6: Baja | V6: Inferencia académica
A7: Ingeniería Electrónica | B7: Semestre 1 | C7: Humanística I | D7: 2 | E7: Complementaria | F7: Formación humanística | G7: Formación humanística, ética y ciudadana | H7: Contenidos humanísticos propios del curso | I7: Baja | J7: Baja | K7: Baja | L7: Baja | M7: — | N7: — | O7: No encaja | P7: Baja | Q7: No requiere simulador — asignatura sin decisiones de gestión, proyecto o negocio | R7: Ninguno | S7: Formación humanística sin contenidos de gestión que justifiquen un simulador. | T7: No aplica | U7: Baja | V7: Inferencia académica
